[2022-09-09T11:14:18.399+0500] {taskinstance.py:1171} INFO - Dependencies all met for <TaskInstance: expectation_dag.expect_mean scheduled__2022-09-08T00:00:00+00:00 [queued]>
[2022-09-09T11:14:18.404+0500] {taskinstance.py:1171} INFO - Dependencies all met for <TaskInstance: expectation_dag.expect_mean scheduled__2022-09-08T00:00:00+00:00 [queued]>
[2022-09-09T11:14:18.404+0500] {taskinstance.py:1368} INFO - 
--------------------------------------------------------------------------------
[2022-09-09T11:14:18.404+0500] {taskinstance.py:1369} INFO - Starting attempt 1 of 1
[2022-09-09T11:14:18.404+0500] {taskinstance.py:1370} INFO - 
--------------------------------------------------------------------------------
[2022-09-09T11:14:18.418+0500] {taskinstance.py:1389} INFO - Executing <Task(PythonOperator): expect_mean> on 2022-09-08 00:00:00+00:00
[2022-09-09T11:14:18.425+0500] {standard_task_runner.py:52} INFO - Started process 1127857 to run task
[2022-09-09T11:14:18.429+0500] {standard_task_runner.py:79} INFO - Running: ['airflow', 'tasks', 'run', 'expectation_dag', 'expect_mean', 'scheduled__2022-09-08T00:00:00+00:00', '--job-id', '60', '--raw', '--subdir', 'DAGS_FOLDER/expectation_dag.py', '--cfg-path', '/tmp/tmp1fu_83bl', '--error-file', '/tmp/tmpzu6x9jox']
[2022-09-09T11:14:18.429+0500] {standard_task_runner.py:80} INFO - Job 60: Subtask expect_mean
[2022-09-09T11:14:18.483+0500] {task_command.py:371} INFO - Running <TaskInstance: expectation_dag.expect_mean scheduled__2022-09-08T00:00:00+00:00 [running]> on host shahroze
[2022-09-09T11:14:18.531+0500] {taskinstance.py:1581} INFO - Exporting the following env vars:
AIRFLOW_CTX_DAG_OWNER=airflow
AIRFLOW_CTX_DAG_ID=expectation_dag
AIRFLOW_CTX_TASK_ID=expect_mean
AIRFLOW_CTX_EXECUTION_DATE=2022-09-08T00:00:00+00:00
AIRFLOW_CTX_TRY_NUMBER=1
AIRFLOW_CTX_DAG_RUN_ID=scheduled__2022-09-08T00:00:00+00:00
[2022-09-09T11:14:18.534+0500] {taskinstance.py:1902} ERROR - Task failed with exception
Traceback (most recent call last):
  File "/usr/local/lib/python3.10/dist-packages/airflow/operators/python.py", line 171, in execute
    return_value = self.execute_callable()
  File "/usr/local/lib/python3.10/dist-packages/airflow/operators/python.py", line 189, in execute_callable
    return self.python_callable(*self.op_args, **self.op_kwargs)
  File "/home/shahroze/airflow/dags/expectations.py", line 27, in expectation2
    raise ValueError('Mean is not in given values')
ValueError: Mean is not in given values
[2022-09-09T11:14:18.537+0500] {taskinstance.py:1407} INFO - Marking task as FAILED. dag_id=expectation_dag, task_id=expect_mean, execution_date=20220908T000000, start_date=20220909T061418, end_date=20220909T061418
[2022-09-09T11:14:18.550+0500] {standard_task_runner.py:92} ERROR - Failed to execute job 60 for task expect_mean (Mean is not in given values; 1127857)
[2022-09-09T11:14:18.560+0500] {local_task_job.py:156} INFO - Task exited with return code 1
[2022-09-09T11:14:18.573+0500] {local_task_job.py:279} INFO - 0 downstream tasks scheduled from follow-on schedule check
