[2022-09-09T11:14:14.973+0500] {taskinstance.py:1171} INFO - Dependencies all met for <TaskInstance: expectation_dag.expect_values_in_set scheduled__2022-09-08T00:00:00+00:00 [queued]>
[2022-09-09T11:14:14.978+0500] {taskinstance.py:1171} INFO - Dependencies all met for <TaskInstance: expectation_dag.expect_values_in_set scheduled__2022-09-08T00:00:00+00:00 [queued]>
[2022-09-09T11:14:14.978+0500] {taskinstance.py:1368} INFO - 
--------------------------------------------------------------------------------
[2022-09-09T11:14:14.978+0500] {taskinstance.py:1369} INFO - Starting attempt 1 of 1
[2022-09-09T11:14:14.978+0500] {taskinstance.py:1370} INFO - 
--------------------------------------------------------------------------------
[2022-09-09T11:14:14.992+0500] {taskinstance.py:1389} INFO - Executing <Task(PythonOperator): expect_values_in_set> on 2022-09-08 00:00:00+00:00
[2022-09-09T11:14:14.996+0500] {standard_task_runner.py:52} INFO - Started process 1127833 to run task
[2022-09-09T11:14:14.998+0500] {standard_task_runner.py:79} INFO - Running: ['airflow', 'tasks', 'run', 'expectation_dag', 'expect_values_in_set', 'scheduled__2022-09-08T00:00:00+00:00', '--job-id', '59', '--raw', '--subdir', 'DAGS_FOLDER/expectation_dag.py', '--cfg-path', '/tmp/tmp9fif3dea', '--error-file', '/tmp/tmpn96sqv6x']
[2022-09-09T11:14:14.998+0500] {standard_task_runner.py:80} INFO - Job 59: Subtask expect_values_in_set
[2022-09-09T11:14:15.035+0500] {task_command.py:371} INFO - Running <TaskInstance: expectation_dag.expect_values_in_set scheduled__2022-09-08T00:00:00+00:00 [running]> on host shahroze
[2022-09-09T11:14:15.079+0500] {taskinstance.py:1581} INFO - Exporting the following env vars:
AIRFLOW_CTX_DAG_OWNER=airflow
AIRFLOW_CTX_DAG_ID=expectation_dag
AIRFLOW_CTX_TASK_ID=expect_values_in_set
AIRFLOW_CTX_EXECUTION_DATE=2022-09-08T00:00:00+00:00
AIRFLOW_CTX_TRY_NUMBER=1
AIRFLOW_CTX_DAG_RUN_ID=scheduled__2022-09-08T00:00:00+00:00
[2022-09-09T11:14:15.083+0500] {taskinstance.py:1902} ERROR - Task failed with exception
Traceback (most recent call last):
  File "/usr/local/lib/python3.10/dist-packages/airflow/operators/python.py", line 171, in execute
    return_value = self.execute_callable()
  File "/usr/local/lib/python3.10/dist-packages/airflow/operators/python.py", line 189, in execute_callable
    return self.python_callable(*self.op_args, **self.op_kwargs)
  File "/home/shahroze/airflow/dags/expectations.py", line 20, in expectation1
    raise ValueError('Values are not in given set')
ValueError: Values are not in given set
[2022-09-09T11:14:15.086+0500] {taskinstance.py:1407} INFO - Marking task as FAILED. dag_id=expectation_dag, task_id=expect_values_in_set, execution_date=20220908T000000, start_date=20220909T061414, end_date=20220909T061415
[2022-09-09T11:14:15.098+0500] {standard_task_runner.py:92} ERROR - Failed to execute job 59 for task expect_values_in_set (Values are not in given set; 1127833)
[2022-09-09T11:14:15.129+0500] {local_task_job.py:156} INFO - Task exited with return code 1
[2022-09-09T11:14:15.142+0500] {local_task_job.py:279} INFO - 0 downstream tasks scheduled from follow-on schedule check
